Workbook

Sheet Slideinfo
A1: WSI name | B1: Cohort | C1: width (x) | D1: height (y) | E1: spacing (x) | F1: spacing (y) | G1: Tumormap QC | H1: Tissuemap QC | I1: Note | J1: QC pass | K1: FinalUse (#N/A = False)
A2: TCGA-3C-AALI-01Z-00-DX1.F6E9A5DF-D8FB-45CF-B4BD-C6B76294C291.svs | B2: TCGA-BRCA | C2: 101184 | D2: 74432 | E2: 0.25 | F2: 0.25 | J2: =AND(G2="",H2="") -> TRUE | K2: =VLOOKUP(A2,IsMaxTumorArea!B$1:C$3437,2,FALSE) -> #N/A
A3: TCGA-3C-AALI-01Z-00-DX2.CF4496E0-AB52-4F3E-BDF5-C34833B91B7C.svs | B3: TCGA-BRCA | C3: 113216 | D3: 81024 | E3: 0.25 | F3: 0.25 | J3: =AND(G3="",H3="") -> TRUE | K3: =VLOOKUP(A3,IsMaxTumorArea!B$1:C$3437,2,FALSE) -> TCGA-BRCA
A4: TCGA-3C-AALJ-01Z-00-DX1.777C0957-255A-42F0-9EEB-A3606BCF0C96.svs | B4: TCGA-BRCA | C4: 95744 | D4: 86336 | E4: 0.25 | F4: 0.25 | J4: =AND(G4="",H4="") -> TRUE | K4: =VLOOKUP(A4,IsMaxTumorArea!B$1:C$3437,2,FALSE) -> TCGA-BRCA
A5: TCGA-3C-AALJ-01Z-00-DX2.62DFE56B-B84C-40F9-9625-FCB55767B70D.svs | B5: TCGA-BRCA | C5: 105152 | D5: 77248 | E5: 0.25 | F5: 0.25 | J5: =AND(G5="",H5="") -> TRUE | K5: =VLOOKUP(A5,IsMaxTumorArea!B$1:C$3437,2,FALSE) -> #N/A
A6: TCGA-3C-AALK-01Z-00-DX1.4E6EB156-BB19-410F-878F-FC0EA7BD0B53.svs | B6: TCGA-BRCA | C6: 95488 | D6: 81920 | E6: 0.25 | F6: 0.25 | J6: =AND(G6="",H6="") -> TRUE | K6: =VLOOKUP(A6,IsMaxTumorArea!B$1:C$3437,2,FALSE) -> TCGA-BRCA
A7: TCGA-4H-AAAK-01Z-00-DX1.ABF1B042-1970-4E28-8671-43AAD393D2F9.svs | B7: TCGA-BRCA | C7: 73704 | D7: 77550 | E7: 0.2525 | F7: 0.2525 | J7: =AND(G7="",H7="") -> TRUE | K7: =VLOOKUP(A7,IsMaxTumorArea!B$1:C$3437,2,FALSE) -> TCGA-BRCA
A8: TCGA-5L-AAT0-01Z-00-DX1.5E171263-30BF-4C6B-88A1-E8EA0522A861.svs | B8: TCGA-BRCA | C8: 61752 | D8: 59840 | E8: 0.2525 | F8: 0.2525 | G8: Non-H&E | H8: Non-H&E | J8: =AND(G8="",H8="") -> FALSE | K8: =VLOOKUP(A8,IsMaxTumorArea!B$1:C$3437,2,FALSE) -> #N/A
A9: TCGA-5L-AAT1-01Z-00-DX1.F3449A5B-2AC4-4ED7-BF44-4C8946CDB47D.svs | B9: TCGA-BRCA | C9: 89640 | D9: 79673 | E9: 0.2525 | F9: 0.2525 | J9: =AND(G9="",H9="") -> TRUE | K9: =VLOOKUP(A9,IsMaxTumorArea!B$1:C$3437,2,FALSE) -> TCGA-BRCA
A10: TCGA-5T-A9QA-01Z-00-DX1.B4212117-E0A7-4EF2-B324-8396042ACEC1.svs | B10: TCGA-BRCA | C10: 103584 | D10: 89511 | E10: 0.2525 | F10: 0.2525 | J10: =AND(G10="",H10="") -> TRUE | K10: =VLOOKUP(A10,IsMaxTumorArea!B$1:C$3437,2,FALSE) -> TCGA-BRCA
A11: TCGA-A1-A0SB-01Z-00-DX1.B34C267B-CAAA-4AB6-AD5C-276C26F997A1.svs | B11: TCGA-BRCA | C11: 112314 | D11: 82945 | E11: 0.25209999 | F11: 0.25209999 | J11: =AND(G11="",H11="") -> TRUE | K11: =VLOOKUP(A11,IsMaxTumorArea!B$1:C$3437,2,FALSE) -> TCGA-BRCA
A12: TCGA-A1-A0SD-01Z-00-DX1.DB17BFA9-D951-42A8-91D2-F4C2EBC6EB9F.svs | B12: TCGA-BRCA | C12: 94075 | D12: 80287 | E12: 0.25209999 | F12: 0.25209999 | J12: =AND(G12="",H12="") -> TRUE | K12: =VLOOKUP(A12,IsMaxTumorArea!B$1:C$3437,2,FALSE) -> TCGA-BRCA
A13: TCGA-A1-A0SE-01Z-00-DX1.04B09232-C6C4-46EF-AA2C-41D078D0A80A.svs | B13: TCGA-BRCA | C13: 122873 | D13: 73336 | E13: 0.25209999 | F13: 0.25209999 | J13: =AND(G13="",H13="") -> TRUE | K13: =VLOOKUP(A13,IsMaxTumorArea!B$1:C$3437,2,FALSE) -> TCGA-BRCA
A14: TCGA-A1-A0SF-01Z-00-DX1.7F252D89-EA78-419F-A969-1B7313D77499.svs | B14: TCGA-BRCA | C14: 65276 | D14: 84727 | E14: 0.25209999 | F14: 0.25209999 | J14: =AND(G14="",H14="") -> TRUE | K14: =VLOOKUP(A14,IsMaxTumorArea!B$1:C$3437,2,FALSE) -> TCGA-BRCA
A15: TCGA-A1-A0SH-01Z-00-DX1.90E71B08-E1D9-4FC2-85AC-062E56DDF17C.svs | B15: TCGA-BRCA | C15: 98874 | D15: 64427 | E15: 0.25209999 | F15: 0.25209999 | J15: =AND(G15="",H15="") -> TRUE | K15: =VLOOKUP(A15,IsMaxTumorArea!B$1:C$3437,2,FALSE) -> TCGA-BRCA
A16: TCGA-A1-A0SI-01Z-00-DX1.AB717348-F964-4F29-BBE2-972B7C640432.svs | B16: TCGA-BRCA | C16: 92155 | D16: 84072 | E16: 0.25209999 | F16: 0.25209999 | J16: =AND(G16="",H16="") -> TRUE | K16: =VLOOKUP(A16,IsMaxTumorArea!B$1:C$3437,2,FALSE) -> TCGA-BRCA
A17: TCGA-A1-A0SJ-01Z-00-DX1.C196FA66-C376-4016-86BC-3D8E745B3A51.svs | B17: TCGA-BRCA | C17: 108474 | D17: 89504 | E17: 0.25209999 | F17: 0.25209999 | J17: =AND(G17="",H17="") -> TRUE | K17: =VLOOKUP(A17,IsMaxTumorArea!B$1:C$3437,2,FALSE) -> TCGA-BRCA
A18: TCGA-A1-A0SK-01Z-00-DX1.A44D70FA-4D96-43F4-9DD7-A61535786297.svs | B18: TCGA-BRCA | C18: 125753 | D18: 75078 | E18: 0.25209999 | F18: 0.25209999 | J18: =AND(G18="",H18="") -> TRUE | K18: =VLOOKUP(A18,IsMaxTumorArea!B$1:C$3437,2,FALSE) -> TCGA-BRCA
A19: TCGA-A1-A0SM-01Z-00-DX1.AD503DBD-4D93-4476-B467-F091254FDF78.svs | B19: TCGA-BRCA | C19: 100794 | D19: 80501 | E19: 0.25209999 | F19: 0.25209999 | J19: =AND(G19="",H19="") -> TRUE | K19: =VLOOKUP(A19,IsMaxTumorArea!B$1:C$3437,2,FALSE) -> TCGA-BRCA
A20: TCGA-A1-A0SN-01Z-00-DX1.5E9B85AE-AFB7-41DC-8A1B-BD6DA39B6540.svs | B20: TCGA-BRCA | C20: 113274 | D20: 72891 | E20: 0.25209999 | F20: 0.25209999 | J20: =AND(G20="",H20="") -> TRUE | K20: =VLOOKUP(A20,IsMaxTumorArea!B$1:C$3437,2,FALSE) -> TCGA-BRCA
... A48: TCGA-A2-A0D0-01Z-00-DX1.4FF6B8E5-703B-400F-920A-104F56E0F874.svs | B48: TCGA-BRCA | C48: 112037 | D48: 88255 | E48: 0.2485 | F48: 0.2485 | J48: =AND(G48="",H48="") -> TRUE | K48: =VLOOKUP(A48,IsMaxTumorArea!B$1:C$3437,2,FALSE) -> TCGA-BRCA
A49: TCGA-A2-A0D3-01Z-00-DX1.D18CE1C0-291D-41C1-8F71-2A0551F8C661.svs | B49: TCGA-BRCA | C49: 103693 | D49: 65863 | E49: 0.25049999 | F49: 0.25049999 | G49: Inaccurate | J49: =AND(G49="",H49="") -> FALSE | K49: =VLOOKUP(A49,IsMaxTumorArea!B$1:C$3437,2,FALSE) -> #N/A
A50: TCGA-A2-A0D4-01Z-00-DX1.35E43827-DABC-4685-A62A-333672923349.svs | B50: TCGA-BRCA | C50: 94801 | D50: 85804 | E50: 0.2485 | F50: 0.2485 | J50: =AND(G50="",H50="") -> TRUE | K50: =VLOOKUP(A50,IsMaxTumorArea!B$1:C$3437,2,FALSE) -> TCGA-BRCA
A51: TCGA-A2-A0EM-01Z-00-DX1.305CF011-7451-4880-9A5D-AB4432CF53A5.svs | B51: TCGA-BRCA | C51: 108207 | D51: 81900 | E51: 0.2485 | F51: 0.2485 | J51: =AND(G51="",H51="") -> TRUE | K51: =VLOOKUP(A51,IsMaxTumorArea!B$1:C$3437,2,FALSE) -> TCGA-BRCA
A52: TCGA-A2-A0EN-01Z-00-DX1.F43A5D17-9267-4963-993A-93AC91BDC031.svs | B52: TCGA-BRCA | C52: 102815 | D52: 88431 | E52: 0.248 | F52: 0.248 | J52: =AND(G52="",H52="") -> TRUE | K52: =VLOOKUP(A52,IsMaxTumorArea!B$1:C$3437,2,FALSE) -> TCGA-BRCA
A53: TCGA-A2-A0EO-01Z-00-DX1.D7A09E23-2CAB-4B3B-814C-BF0BA75B7589.svs | B53: TCGA-BRCA | C53: 106292 | D53: 74771 | E53: 0.2485 | F53: 0.2485 | J53: =AND(G53="",H53="") -> TRUE | K53: =VLOOKUP(A53,IsMaxTumorArea!B$1:C$3437,2,FALSE) -> TCGA-BRCA
A54: TCGA-A2-A0EP-01Z-00-DX1.1180C406-5C18-4373-8621-1B7B70875113.svs | B54: TCGA-BRCA | C54: 112336 | D54: 74817 | E54: 0.2456 | F54: 0.2456 | J54: =AND(G54="",H54="") -> TRUE | K54: =VLOOKUP(A54,IsMaxTumorArea!B$1:C$3437,2,FALSE) -> TCGA-BRCA
A55: TCGA-A2-A0EQ-01Z-00-DX1.5FCD8890-4594-4BE2-93B1-B8F698BFD2A0.svs | B55: TCGA-BRCA | C55: 121613 | D55: 87178 | E55: 0.2485 | F55: 0.2485 | J55: =AND(G55="",H55="") -> TRUE | K55: =VLOOKUP(A55,IsMaxTumorArea!B$1:C$3437,2,FALSE) -> TCGA-BRCA
A56: TCGA-A2-A0ER-01Z-00-DX1.18123C1B-A0CC-4957-9373-5FFAB985C2E8.svs | B56: TCGA-BRCA | C56: 70861 | D56: 79312 | E56: 0.2485 | F56: 0.2485 | J56: =AND(G56="",H56="") -> TRUE | K56: =VLOOKUP(A56,IsMaxTumorArea!B$1:C$3437,2,FALSE) -> TCGA-BRCA
A57: TCGA-A2-A0ES-01Z-00-DX1.5652EE30-48C1-4EC1-AD77-8C72DFCB9A97.svs | B57: TCGA-BRCA | C57: 174742 | D57: 72773 | E57: 0.25049999 | F57: 0.25049999 | J57: =AND(G57="",H57="") -> TRUE | K57: =VLOOKUP(A57,IsMaxTumorArea!B$1:C$3437,2,FALSE) -> TCGA-BRCA
A58: TCGA-A2-A0ET-01Z-00-DX1.41E86BB9-EA52-4615-94E7-0F09DDB094F4.svs | B58: TCGA-BRCA | C58: 90970 | D58: 88630 | E58: 0.2485 | F58: 0.2485 | J58: =AND(G58="",H58="") -> TRUE | K58: =VLOOKUP(A58,IsMaxTumorArea!B$1:C$3437,2,FALSE) -> TCGA-BRCA
A59: TCGA-A2-A0EU-01Z-00-DX1.13335BEB-63D4-469B-A389-8A079A096129.svs | B59: TCGA-BRCA | C59: 84267 | D59: 76940 | E59: 0.2485 | F59: 0.2485 | J59: =AND(G59="",H59="") -> TRUE | K59: =VLOOKUP(A59,IsMaxTumorArea!B$1:C$3437,2,FALSE) -> TCGA-BRCA
A60: TCGA-A2-A0EV-01Z-00-DX1.EA8C5594-BA4F-47A8-949B-D536E00E62C9.svs | B60: TCGA-BRCA | C60: 173323 | D60: 78453 | E60: 0.2485 | F60: 0.2485 | J60: =AND(G60="",H60="") -> TRUE | K60: =VLOOKUP(A60,IsMaxTumorArea!B$1:C$3437,2,FALSE) -> TCGA-BRCA
A61: TCGA-A2-A0EW-01Z-00-DX1.F24495CB-63D8-483F-9834-F761E3F16BF0.svs | B61: TCGA-BRCA | C61: 90251 | D61: 51995 | E61: 0.25049999 | F61: 0.25049999 | J61: =AND(G61="",H61="") -> TRUE | K61: =VLOOKUP(A61,IsMaxTumorArea!B$1:C$3437,2,FALSE) -> TCGA-BRCA
... A123: TCGA-A7-A0CD-01Z-00-DX1.F045B9C8-049C-41BF-8432-EF89F236D34D.svs | B123: TCGA-BRCA | C123: 96152 | D123: 37492 | E123: 0.2465 | F123: 0.2465 | J123: =AND(G123="",H123="") -> TRUE | K123: =VLOOKUP(A123,IsMaxTumorArea!B$1:C$3437,2,FALSE) -> TCGA-BRCA
A124: TCGA-A7-A0CD-01Z-00-DX2.609CED8D-5947-4753-A75B-73A8343B47EC.svs | B124: TCGA-BRCA | C124: 93296 | D124: 45453 | E124: 0.2465 | F124: 0.2465 | G124: No tumor region | J124: =AND(G124="",H124="") -> FALSE | K124: =VLOOKUP(A124,IsMaxTumorArea!B$1:C$3437,2,FALSE) -> #N/A
A125: TCGA-A7-A0CE-01Z-00-DX1.E67322FB-ED25-4B85-B3B0-2B8BD277BB4A.svs | B125: TCGA-BRCA | C125: 191352 | D125: 58998 | E125: 0.2465 | F125: 0.2465 | J125: =AND(G125="",H125="") -> TRUE | K125: =VLOOKUP(A125,IsMaxTumorArea!B$1:C$3437,2,FALSE) -> TCGA-BRCA
A126: TCGA-A7-A0CE-01Z-00-DX2.5AD1DB65-10E7-4996-AB5E-13D7851EC5FA.svs | B126: TCGA-BRCA | C126: 131376 | D126: 54056 | E126: 0.2465 | F126: 0.2465 | J126: =AND(G126="",H126="") -> TRUE | K126: =VLOOKUP(A126,IsMaxTumorArea!B$1:C$3437,2,FALSE) -> #N/A
A127: TCGA-A7-A0CG-01Z-00-DX1.D77019C2-96B1-4EF5-A61E-5F2D5B8D9852.svs | B127: TCGA-BRCA | C127: 142800 | D127: 34647 | E127: 0.2465 | F127: 0.2465 | J127: =AND(G127="",H127="") -> TRUE | K127: =VLOOKUP(A127,IsMaxTumorArea!B$1:C$3437,2,FALSE) -> #N/A
A128: TCGA-A7-A0CG-01Z-00-DX2.81138E90-373A-4C12-B9CA-6EEF5F84A5B5.svs | B128: TCGA-BRCA | C128: 151368 | D128: 38456 | E128: 0.2465 | F128: 0.2465 | J128: =AND(G128="",H128="") -> TRUE | K128: =VLOOKUP(A128,IsMaxTumorArea!B$1:C$3437,2,FALSE) -> TCGA-BRCA
...

Sheet IsMaxTumorArea
A1: Barcode | B1: Slidename | C1: Cohort
A2: TCGA-2E-A9G8 | B2: TCGA-2E-A9G8-01Z-00-DX1.DCD3E31B-1774-40BA-805F-52FB9801D6C0.svs | C2: =VLOOKUP(B2,Slideinfo!A$2:B$3947,2,FALSE) -> TCGA-UCEC
A3: TCGA-2J-AAB1 | B3: TCGA-2J-AAB1-01Z-00-DX1.F3B4818F-9C3B-4C66-8241-0570B2873EC9.svs | C3: =VLOOKUP(B3,Slideinfo!A$2:B$3947,2,FALSE) -> TCGA-PAAD
A4: TCGA-2J-AAB4 | B4: TCGA-2J-AAB4-01Z-00-DX1.480BBC89-87E5-4F6B-B0E9-A6A8A7F4DB5E.svs | C4: =VLOOKUP(B4,Slideinfo!A$2:B$3947,2,FALSE) -> TCGA-PAAD
A5: TCGA-2J-AAB6 | B5: TCGA-2J-AAB6-01Z-00-DX1.2FC4D66F-BFBB-48FA-AFCB-ABBC12F37E14.svs | C5: =VLOOKUP(B5,Slideinfo!A$2:B$3947,2,FALSE) -> TCGA-PAAD
A6: TCGA-2J-AAB8 | B6: TCGA-2J-AAB8-01Z-00-DX1.6ED96ECC-50A5-4957-A7A8-EDDC0E3447AF.svs | C6: =VLOOKUP(B6,Slideinfo!A$2:B$3947,2,FALSE) -> TCGA-PAAD
A7: TCGA-2J-AAB9 | B7: TCGA-2J-AAB9-01Z-00-DX1.F39B4CC5-02D0-4F38-90B5-CDF507EEABE1.svs | C7: =VLOOKUP(B7,Slideinfo!A$2:B$3947,2,FALSE) -> TCGA-PAAD
A8: TCGA-2J-AABE | B8: TCGA-2J-AABE-01Z-00-DX1.F3951485-1412-4B86-80FB-64F72A2A87DD.svs | C8: =VLOOKUP(B8,Slideinfo!A$2:B$3947,2,FALSE) -> TCGA-PAAD
A9: TCGA-2J-AABF | B9: TCGA-2J-AABF-01Z-00-DX1.4895FC60-5DC3-4B36-97AB-634AC54E5B3E.svs | C9: =VLOOKUP(B9,Slideinfo!A$2:B$3947,2,FALSE) -> TCGA-PAAD
A10: TCGA-2J-AABH | B10: TCGA-2J-AABH-01Z-00-DX1.EDC36BC9-F6F9-4253-93FB-8B75D8D55BE0.svs | C10: =VLOOKUP(B10,Slideinfo!A$2:B$3947,2,FALSE) -> TCGA-PAAD
A11: TCGA-2J-AABI | B11: TCGA-2J-AABI-01Z-00-DX1.3D4AC096-FF28-4BAE-9DA2-43247C36BD24.svs | C11: =VLOOKUP(B11,Slideinfo!A$2:B$3947,2,FALSE) -> TCGA-PAAD
A12: TCGA-2J-AABK | B12: TCGA-2J-AABK-01Z-00-DX1.AF5DE1FD-40EE-4149-8918-B53EC2DF727E.svs | C12: =VLOOKUP(B12,Slideinfo!A$2:B$3947,2,FALSE) -> TCGA-PAAD
A13: TCGA-2J-AABO | B13: TCGA-2J-AABO-01Z-00-DX1.0AFA66C7-C6F7-4B74-AA3E-8900F231A193.svs | C13: =VLOOKUP(B13,Slideinfo!A$2:B$3947,2,FALSE) -> TCGA-PAAD
... A3438: TCGA-ZQ-A9CR | B3438: TCGA-ZQ-A9CR-01Z-00-DX1.C9AC9991-7054-4068-A7AA-9D1EB7F040A3.svs | C3438: =VLOOKUP(B3438,Slideinfo!A$2:B$3947,2,FALSE) -> TCGA-STAD

Sheet Sheet1
A3: 行标签 | B3: 计数项:Barcode
A4: TCGA-BRCA | B4: 1010
A5: TCGA-COAD | B5: 420
A6: TCGA-LUAD | B6: 455
A7: TCGA-LUSC | B7: 455
A8: TCGA-OV | B8: 101
A9: TCGA-PAAD | B9: 165
A10: TCGA-STAD | B10: 356
A11: TCGA-UCEC | B11: 475
A12: 总计 | B12: 3437
